<?xml version="1.0" encoding="utf-8"?>
<!-- =================================================================================== -->
<!-- |    This document was autogenerated by xacro from blue_right_v2.urdf.xacro       | -->
<!-- |    EDITING THIS FILE BY HAND IS NOT RECOMMENDED                                 | -->
<!-- =================================================================================== -->
<robot name="blue_descriptions_right">
  <!-- ====== Robot arm colors definition ====== -->
  <material name="roll_link_v2">
    <color rgba="0.36 0.36 0.36 1"/>
  </material>
  <material name="lift_link_v2">
    <color rgba="0.68 0.93 0.99 1"/>
  </material>
  <material name="arm_base_link_v2">
    <color rgba="0.3 0.3 0.3 1"/>
  </material>
  <!-- ====== Robot hand colors definition ====== -->
  <material name="hand_base_link">
    <color rgba="0.36 0.36 0.36 1"/>
  </material>
  <material name="finger_limb_link">
    <color rgba="0.2 0.2 0.2 1"/>
  </material>
  <material name="finger_tip_link">
    <color rgba="0.68 0.93 0.99 1"/>
  </material>
  <link name="base_link">
    </link>
  <joint name="right_fixed_joint" type="fixed">
    <origin rpy="0.0 0.0 0.0" xyz="0.0 0.0 0.0"/>
    <parent link="base_link"/>
    <child link="right_base_link"/>
    <axis xyz="0.0 0.0 0.0"/>
  </joint>
  <!-- ad -->
  <link name="right_base_link">
    <inertial>
      <origin rpy="0 0 0" xyz="0.10796437546629 -0.000118075432376297 0.0740606975550663"/>
      <mass value="3.45160966669018"/>
      <inertia ixx="0.00801268059065087" ixy="-2.57142344841348E-05" ixz="-0.00260219134387606" iyy="0.0157384822948846" iyz="-9.21399274816697E-06" izz="0.0168436725169874"/>
    </inertial>
    <visual>
      <origin rpy="0 0 0" xyz="0 0 0"/>
      <geometry>
        <mesh filename="meshes/arm_base_link_v2.STL"/>
      </geometry>
      <material name="arm_base_link_v2"/>
    </visual>
    <collision>
      <origin rpy="0 0 0" xyz="0 0 0"/>
      <geometry>
        <mesh filename="meshes/arm_base_link_v2.STL"/>
      </geometry>
    </collision>
  </link>
  <joint name="right_base_roll_joint" type="revolute">
    <dynamics damping="0.7" friction="10.0"/>
    <origin rpy="3.14159265358979 -1.1927577496737E-15 2.81382558958119E-17" xyz="0 0 0.0834989807730001"/>
    <parent link="right_base_link"/>
    <child link="right_shoulder_roll_link"/>
    <axis xyz="0 0 1"/>
    <limit effort="800" lower="-3.1" upper="3.14159" velocity="50"/>
  </joint>
  <link name="right_shoulder_roll_link">
    <inertial>
      <origin rpy="0 0 0" xyz="0.0069 -0.0001 -0.1116"/>
      <mass value="1.83492"/>
      <inertia ixx="61495.01E-07" ixy="-19.9700E-07" ixz="328.6000E-07" iyy="50978.60E-07" iyz="243.2100E-07" izz="41841.05E-07"/>
    </inertial>
    <visual>
      <origin rpy="0 0 0" xyz="0 0 0"/>
      <geometry>
        <mesh filename="meshes/roll_link_v2.STL"/>
      </geometry>
      <material name="roll_link_v2"/>
    </visual>
    <collision>
      <origin rpy="0 0 0" xyz="0 0 0"/>
      <geometry>
        <mesh filename="meshes/roll_link_v2.STL"/>
      </geometry>
    </collision>
  </link>
  <joint name="right_shoulder_lift_joint" type="revolute">
    <dynamics damping="0.7" friction="10.0"/>
    <origin rpy="-1.5707963267949 -4.98868359282976E-16 2.07570761486143E-16" xyz="-0.012 0 -0.232779056600415"/>
    <parent link="right_shoulder_roll_link"/>
    <child link="right_shoulder_lift_link"/>
    <axis xyz="0 0 -1"/>
    <!-- lower="-2.3911" upper="0.3316" was the default value -->
    <limit effort="800" lower="-2.3911" upper="1.69" velocity="50"/>
  </joint>
  <link name="right_shoulder_accel_link"/>
  <joint name="right_shoulder_accel_joint" type="fixed">
    <dynamics damping="0.7" friction="10.0"/>
    <origin rpy="1.5707963267949 0.328491802364426 5.16250107234938E-16" xyz="-0.020008330615085 -0.000510000000000066 -0.111067108096273"/>
    <parent link="right_shoulder_roll_link"/>
    <child link="right_shoulder_accel_link"/>
    <axis xyz="0 0 0"/>
  </joint>
  <link name="right_shoulder_lift_link">
    <inertial>
      <origin rpy="0 0 0" xyz="0.0 0.01524 0.0"/>
      <mass value="0.58967"/>
      <inertia ixx="11631.35E-07" ixy="0.000000E-07" ixz="0.000000E-07" iyy="9852.210E-07" iyz="0.000000E-07" izz="8916.610E-07"/>
    </inertial>
    <visual>
      <origin rpy="0 0 0" xyz="0 0 0"/>
      <geometry>
        <mesh filename="meshes/lift_link_v2.STL"/>
      </geometry>
      <material name="lift_link_v2"/>
    </visual>
    <collision>
      <origin rpy="0 0 0" xyz="0 0 0"/>
      <geometry>
        <mesh filename="meshes/lift_link_v2.STL"/>
      </geometry>
    </collision>
  </link>
  <joint name="right_shoulder_roll_joint" type="revolute">
    <dynamics damping="0.7" friction="10.0"/>
    <origin rpy="1.5707963267949 1.56798 0" xyz="0 0.035953152113 0"/>
    <parent link="right_shoulder_lift_link"/>
    <child link="right_elbow_roll_link"/>
    <axis xyz="0 0 1"/>
    <limit effort="800" lower="-2.6761" upper="2.6761" velocity="50"/>
  </joint>
  <link name="right_elbow_roll_link">
    <inertial>
      <origin rpy="0 0 0" xyz="0.0069 -0.0001 -0.1116"/>
      <mass value="1.83492"/>
      <inertia ixx="61495.01E-07" ixy="-19.9700E-07" ixz="328.6000E-07" iyy="50978.60E-07" iyz="243.2100E-07" izz="41841.05E-07"/>
    </inertial>
    <visual>
      <origin rpy="0 0 0" xyz="0 0 0"/>
      <geometry>
        <mesh filename="meshes/roll_link_v2.STL"/>
      </geometry>
      <material name="roll_link_v2"/>
    </visual>
    <collision>
      <origin rpy="0 0 0" xyz="0 0 0"/>
      <geometry>
        <mesh filename="meshes/roll_link_v2.STL"/>
      </geometry>
    </collision>
  </link>
  <joint name="right_elbow_lift_joint" type="revolute">
    <dynamics damping="0.7" friction="10.0"/>
    <origin rpy="-1.5707963267949 -4.98868359282976E-16 2.07570761486143E-16" xyz="-0.012 0 -0.232779056600415"/>
    <parent link="right_elbow_roll_link"/>
    <child link="right_elbow_lift_link"/>
    <axis xyz="0 0 -1"/>
    <!-- lower="-2.3911" upper="0.3316" was the default value -->
    <limit effort="800" lower="-2.3911" upper="1.69" velocity="50"/>
  </joint>
  <link name="right_elbow_accel_link"/>
  <joint name="right_elbow_accel_joint" type="fixed">
    <dynamics damping="0.7" friction="10.0"/>
    <origin rpy="1.5707963267949 0.328491802364426 5.16250107234938E-16" xyz="-0.020008330615085 -0.000510000000000066 -0.111067108096273"/>
    <parent link="right_elbow_roll_link"/>
    <child link="right_elbow_accel_link"/>
    <axis xyz="0 0 0"/>
  </joint>
  <link name="right_elbow_lift_link">
    <inertial>
      <origin rpy="0 0 0" xyz="0.0 0.01524 0.0"/>
      <mass value="0.58967"/>
      <inertia ixx="11631.35E-07" ixy="0.000000E-07" ixz="0.000000E-07" iyy="9852.210E-07" iyz="0.000000E-07" izz="8916.610E-07"/>
    </inertial>
    <visual>
      <origin rpy="0 0 0" xyz="0 0 0"/>
      <geometry>
        <mesh filename="meshes/lift_link_v2.STL"/>
      </geometry>
      <material name="lift_link_v2"/>
    </visual>
    <collision>
      <origin rpy="0 0 0" xyz="0 0 0"/>
      <geometry>
        <mesh filename="meshes/lift_link_v2.STL"/>
      </geometry>
    </collision>
  </link>
  <joint name="right_elbow_roll_joint" type="revolute">
    <dynamics damping="0.7" friction="10.0"/>
    <origin rpy="1.5707963267949 -1.56798 0" xyz="0 0.035953152113 0"/>
    <parent link="right_elbow_lift_link"/>
    <child link="right_wrist_roll_link"/>
    <axis xyz="0 0 1"/>
    <limit effort="800" lower="-2.6761" upper="2.6761" velocity="50"/>
  </joint>
  <link name="right_wrist_roll_link">
    <inertial>
      <origin rpy="0 0 0" xyz="0.0069 -0.0001 -0.1116"/>
      <mass value="1.4651"/>
      <inertia ixx="61495.01E-07" ixy="-19.9700E-07" ixz="328.6000E-07" iyy="50978.60E-07" iyz="243.2100E-07" izz="41841.05E-07"/>
    </inertial>
    <visual>
      <origin rpy="0 0 0" xyz="0 0 0"/>
      <geometry>
        <mesh filename="meshes/roll_link_v2.STL"/>
      </geometry>
      <material name="roll_link_v2"/>
    </visual>
    <collision>
      <origin rpy="0 0 0" xyz="0 0 0"/>
      <geometry>
        <mesh filename="meshes/roll_link_v2.STL"/>
      </geometry>
    </collision>
  </link>
  <joint name="right_wrist_lift_joint" type="revolute">
    <dynamics damping="0.7" friction="10.0"/>
    <origin rpy="-1.5707963267949 -4.98868359282976E-16 2.07570761486143E-16" xyz="-0.012 0 -0.232779056600415"/>
    <parent link="right_wrist_roll_link"/>
    <child link="right_wrist_lift_link"/>
    <axis xyz="0 0 -1"/>
    <!-- lower="-2.3911" upper="0.3316" was the default value -->
    <limit effort="800" lower="-2.3911" upper="1.69" velocity="50"/>
  </joint>
  <link name="right_wrist_accel_link"/>
  <joint name="right_wrist_accel_joint" type="fixed">
    <dynamics damping="0.7" friction="10.0"/>
    <origin rpy="1.5707963267949 0.328491802364426 5.16250107234938E-16" xyz="-0.020008330615085 -0.000510000000000066 -0.111067108096273"/>
    <parent link="right_wrist_roll_link"/>
    <child link="right_wrist_accel_link"/>
    <axis xyz="0 0 0"/>
  </joint>
  <link name="right_wrist_lift_link">
    <inertial>
      <origin rpy="0 0 0" xyz="0.0 0.01524 0.0"/>
      <mass value="0.44906"/>
      <inertia ixx="11631.35E-07" ixy="0.000000E-07" ixz="0.000000E-07" iyy="9852.210E-07" iyz="0.000000E-07" izz="8916.610E-07"/>
    </inertial>
    <visual>
      <origin rpy="0 0 0" xyz="0 0 0"/>
      <geometry>
        <mesh filename="meshes/lift_link_v2.STL"/>
      </geometry>
      <material name="lift_link_v2"/>
    </visual>
    <collision>
      <origin rpy="0 0 0" xyz="0 0 0"/>
      <geometry>
        <mesh filename="meshes/lift_link_v2.STL"/>
      </geometry>
    </collision>
  </link>
  <joint name="right_wrist_roll_joint" type="revolute">
    <dynamics damping="0.7" friction="10.0"/>
    <origin rpy="1.5707963267949 -0.0 0" xyz="0 0.070143152113 0"/>
    <parent link="right_wrist_lift_link"/>
    <child link="right_end_roll_link"/>
    <axis xyz="0 0 1"/>
    <limit effort="800" lower="-2.6761" upper="2.6761" velocity="50"/>
  </joint>
  <link name="right_end_roll_link">
    <inertial>
      <origin rpy="0 0 0" xyz="0.00526385736219506 2.70691865020822E-05 -0.0641638075944594"/>
      <mass value="0.687109755986862"/>
      <inertia ixx="0.0057866591250737" ixy="3.71515699629511E-07" ixz="-6.32890111626103E-05" iyy="0.00530223654324281" iyz="8.9999884666805E-07" izz="0.00342399181200673"/>
    </inertial>
    <visual>
      <origin rpy="0 0 0" xyz="0 0 0"/>
      <geometry>
        <mesh filename="meshes/hand_base_link.STL"/>
      </geometry>
      <material name="hand_base_link"/>
    </visual>
    <collision>
      <origin rpy="0 0 0" xyz="0 0 0"/>
      <geometry>
        <mesh filename="meshes/hand_base_link.STL"/>
      </geometry>
    </collision>
  </link>
  <link name="right_gripper_link">
    <inertial>
      <origin rpy="0 0 0" xyz="-7.00549073506807E-05 2.51271935254316E-05 -0.052367118189184"/>
      <mass value="0.0047109755986862"/>
      <inertia ixx="0.000916887873826385" ixy="-6.04547948818479E-08" ixz="0.6796133363069E-06" iyy="0.000877268801166351" iyz="0.64172907801915E-07" izz="0.000293333065172452"/>
    </inertial>
  </link>
  <joint name="right_gripper_joint" type="revolute">
    <dynamics damping="0.7" friction="10.0"/>
    <origin rpy="1.5 1.5 0" xyz="0 0 -0.10"/>
    <parent link="right_end_roll_link"/>
    <child link="right_gripper_link"/>
    <axis xyz="0 0 1"/>
    <limit effort="800" lower="0" upper="1.05" velocity="50"/>
  </joint>
  <!-- right finger -->
  <link name="right_r_finger_link">
    <inertial>
      <origin rpy="0 0 0" xyz="0.00046733152633803 0.0122666320844707 1.16452530510985E-07"/>
      <mass value="0.0384620979765985"/>
      <inertia ixx="1.93716279065148E-05" ixy="-1.74835869619804E-06" ixz="3.21020594362941E-11" iyy="5.23390911087335E-06" iyz="-5.04535602261134E-11" izz="1.92560542157392E-05"/>
    </inertial>
    <visual>
      <origin rpy="0 0 0" xyz="0 0 0"/>
      <geometry>
        <mesh filename="meshes/finger_limb_link.STL"/>
      </geometry>
      <material name="finger_limb_link"/>
    </visual>
    <collision>
      <origin rpy="0 0 0" xyz="0 0 0"/>
      <geometry>
        <mesh filename="meshes/finger_limb_link.STL"/>
      </geometry>
    </collision>
  </link>
  <joint name="right_r_finger_joint" type="continuous">
    <dynamics damping="0.7" friction="10.0"/>
    <origin rpy="-1.5708 -0.63969 1.5708" xyz="0.000 0.030703 -0.071979"/>
    <parent link="right_end_roll_link"/>
    <child link="right_r_finger_link"/>
    <axis xyz="0 0 1"/>
    <mimic joint="right_gripper_joint" multiplier="1"/>
  </joint>
  <link name="right_r_finger_tip_link">
    <inertial>
      <origin rpy="0 0 0" xyz="0.000428096363398578 -6.3962924111774E-08 0.0162809660053768"/>
      <mass value="0.0096424502794395"/>
      <inertia ixx="1.76146900164229E-06" ixy="-1.63725174281941E-11" ixz="-5.09403577370148E-07" iyy="1.95368501856251E-06" iyz="-2.7403586363238E-12" izz="6.78506827465793E-07"/>
    </inertial>
    <visual>
      <origin rpy="0 0 0" xyz="0 0 0"/>
      <geometry>
        <mesh filename="meshes/finger_tip_link.STL"/>
      </geometry>
      <material name="finger_tip_link"/>
    </visual>
    <collision>
      <origin rpy="0 0 0" xyz="0 0 0"/>
      <geometry>
        <mesh filename="meshes/finger_tip_link.STL"/>
      </geometry>
    </collision>
  </link>
  <joint name="right_r_finger_tip_joint" type="continuous">
    <dynamics damping="0.7" friction="10.0"/>
    <origin rpy="1.5708 -1.5754E-31 -2.5019" xyz="0 0.06 0"/>
    <parent link="right_r_finger_link"/>
    <child link="right_r_finger_tip_link"/>
    <axis xyz="0 1 0"/>
    <mimic joint="right_gripper_joint" max_effort="5" multiplier="-1" offset="0"/>
  </joint>
  <!-- left finger -->
  <link name="right_l_finger_link">
    <inertial>
      <origin rpy="0 0 0" xyz="0.00046733152633803 0.0122666320844707 1.16452530510985E-07"/>
      <mass value="0.0384620979765985"/>
      <inertia ixx="1.93716279065148E-05" ixy="-1.74835869619804E-06" ixz="3.21020594362941E-11" iyy="5.23390911087335E-06" iyz="-5.04535602261134E-11" izz="1.92560542157392E-05"/>
    </inertial>
    <visual>
      <origin rpy="0 0 0" xyz="0 0 0"/>
      <geometry>
        <mesh filename="meshes/finger_limb_link.STL"/>
      </geometry>
      <material name="finger_limb_link"/>
    </visual>
    <collision>
      <origin rpy="0 0 0" xyz="0 0 0"/>
      <geometry>
        <mesh filename="meshes/finger_limb_link.STL"/>
      </geometry>
    </collision>
  </link>
  <joint name="right_l_finger_joint" type="continuous">
    <dynamics damping="0.7" friction="10.0"/>
    <origin rpy="-1.5708 -0.63969 -1.5708" xyz="0.000 -0.030703 -0.071979"/>
    <parent link="right_end_roll_link"/>
    <child link="right_l_finger_link"/>
    <axis xyz="0 0 1"/>
    <mimic joint="right_gripper_joint" multiplier="1"/>
  </joint>
  <link name="right_l_finger_tip_link">
    <inertial>
      <origin rpy="0 0 0" xyz="0.000428096363398578 -6.3962924111774E-08 0.0162809660053768"/>
      <mass value="0.0096424502794395"/>
      <inertia ixx="1.76146900164229E-06" ixy="-1.63725174281941E-11" ixz="-5.09403577370148E-07" iyy="1.95368501856251E-06" iyz="-2.7403586363238E-12" izz="6.78506827465793E-07"/>
    </inertial>
    <visual>
      <origin rpy="0 0 0" xyz="0 0 0"/>
      <geometry>
        <mesh filename="meshes/finger_tip_link.STL"/>
      </geometry>
      <material name="finger_tip_link"/>
    </visual>
    <collision>
      <origin rpy="0 0 0" xyz="0 0 0"/>
      <geometry>
        <mesh filename="meshes/finger_tip_link.STL"/>
      </geometry>
    </collision>
  </link>
  <joint name="right_l_finger_tip_joint" type="continuous">
    <dynamics damping="0.7" friction="10.0"/>
    <origin rpy="1.5708 -1.5754E-31 -2.5019" xyz="0 0.06 0"/>
    <parent link="right_l_finger_link"/>
    <child link="right_l_finger_tip_link"/>
    <axis xyz="0 1 0"/>
    <mimic joint="right_gripper_joint" max_effort="5" multiplier="-1" offset="0"/>
  </joint>
  <link name="right_gripper_finger_link">
    </link>
  <joint name="right_gripper_finger_joint" type="fixed">
    <dynamics damping="0.7" friction="10.0"/>
    <origin rpy="1.5708 1.5708 1.5708" xyz="0 0.0 -0.18"/>
    <parent link="right_end_roll_link"/>
    <child link="right_gripper_finger_link"/>
  </joint>
</robot>

